<?xml version="1.0"?>
<robot xmlns:xacro="http://www.ros.org/wiki/xacro">

    <xacro:include filename="inertial_macros.xacro"/>

    <material name="white">
        <color rgba = "1 1 1 1"/>
    </material>
    <material name="orange">
        <color rgba = "1 0.3 0.1 1"/>
    </material>    
    <material name="blue">
        <color rgba = "0.2 0.2 1 1"/>
    </material>
    <material name="black">
        <color rgba = "0 0 0 1"/>
    </material>

    <!-- BASE  LINK -->
    <link name="base_link"></link>

    <!-- CHASSIS -->
    <joint name="chassis_joint" type="fixed">
        <parent link="base_link"/>
        <child link="chassis"/>
        <origin xyz="-0.04 0 0"/>
    </joint>

    <link name="chassis">
        <visual>
            <origin xyz="0.1016 0 0.01905"/>
            <geometry>
                <!-- skinny version of chassis-->
                <box size="0.2032 0.03815 0.0381"/> 
                <!-- <box size="0.2032 0.0762 0.0381"/> -->
            </geometry>
            <material name="white"/>
        </visual>

        <collision>
            <origin xyz="0.1016 0 0.01905"/>
            <geometry>
                <box size="0.2032 0.03815 0.0381"/> <!-- skinny version of chassis-->
            </geometry>
        </collision> 
        <!-- skinny chassis-->
        <xacro:inertial_box mass="0.5" x="0.2032" y="0.03815" z="0.0381"> 
        <!-- <xacro:inertial_box mass="0.5" x="0.2032" y="0.0762" z="0.0381"> -->
            <origin xyz="0.1016 0 0.01905" rpy="0 0 0"/>
        </xacro:inertial_box> 
    </link>
    
    <gazebo reference="chassis">
        <material>Gazebo/White</material>
    </gazebo>

    <!--LEFT REAR DRIVE WHEEL-->
    <joint name="left_wheel_joint" type="continuous">
        <parent link="base_link"/>
        <child link="left_wheel"/>
        <origin xyz="0 0.0431 0" rpy="-${pi/2} 0 0"/>
        <axis xyz="0 0 1"/>
    </joint>
    <link name="left_wheel">
        <visual>
            <geometry>
                <cylinder radius="0.0325" length="0.01"/>
            </geometry>
            <material name="blue"/>
        </visual>
        <collision>
            <geometry>
                <cylinder radius="0.0325" length="0.01"/>
            </geometry>
        </collision>
        <xacro:inertial_cylinder mass="0.1" length="0.01" radius="0.0325">
            <origin xyz="0 0 0" rpy="0 0 0"/>
        </xacro:inertial_cylinder>
    </link>

    <!--RIGHT REAR DRIVE WHEEL-->
    <joint name="right_wheel_joint" type="continuous">
        <parent link="base_link"/>
        <child link="right_wheel"/>
        <origin xyz="0 -0.0431 0" rpy="${pi/2} 0 0"/>
        <axis xyz="0 0 -1"/>
    </joint>

    <link name="right_wheel">
        <visual>
            <geometry>
                <cylinder radius="0.0325" length="0.01"/>
            </geometry>
            <material name="blue"/>
        </visual>
        <collision>
            <geometry>
                <cylinder radius="0.0325" length="0.01"/>
            </geometry>
        </collision>
        <xacro:inertial_cylinder mass="0.1" length="0.01" radius="0.0325">
            <origin xyz="0 0 0" rpy="0 0 0"/>
        </xacro:inertial_cylinder>
    </link>

    <!--LEFT FRONT WHEEL LINK-->
    <joint name="left_front_wheel_joint" type="continuous">
        <parent link="base_link"/>
        <child link="left_front_wheel"/>
        <origin xyz="0.1 0.0431 0" rpy="-${pi/2} 0 0"/>
        <axis xyz="0 0 1"/>
    </joint>

    <link name="left_front_wheel">
        <visual>
            <geometry>
                <cylinder radius="0.0325" length="0.01"/>
            </geometry>
            <material name="blue"/>
        </visual>
        <collision>
            <geometry>
                <cylinder radius="0.0325" length="0.01"/>
            </geometry>
        </collision>
        <xacro:inertial_cylinder mass="0.1" length="0.01" radius="0.0325">
            <origin xyz="0 0 0" rpy="0 0 0"/>
        </xacro:inertial_cylinder>
    </link>
    <!--RIGHT FRONT WHEEL LINK-->

    <joint name="right_front_wheel_joint" type="continuous">
        <parent link="base_link"/>
        <child link="right_front_wheel"/>
        <origin xyz="1 -0.0431 0" rpy="${pi/2} 0 0"/>
        <axis xyz="0 0 -1"/>
    </joint>

    <link name="right_front_wheel">
        <visual>
            <geometry>
                <cylinder radius="0.0325" length="0.01"/>
            </geometry>
            <material name="blue"/>
        </visual>
        <collision>
            <geometry>
                <cylinder radius="0.0325" length="0.01"/>
            </geometry>
        </collision>
        <xacro:inertial_cylinder mass="0.1" length="0.01" radius="0.0325">
            <origin xyz="0 0 0" rpy="0 0 0"/>
        </xacro:inertial_cylinder>
    </link>
</robot>